timestamp,category,user_id,function,line_number,flag,message,exception
2024-06-08 15:01:42,ERROR,asif24,create_or_pass_folder,197,0,Function create_or_pass_folder error,"Function create_or_pass_folder error
Traceback (most recent call last):
  File ""C:\Users\Asif\Desktop\New_version_CogniLink\app.py"", line 190, in create_or_pass_folder
    container_client.get_blob_client(container_name, user_folder).upload_blob("""")
  File ""C:\Users\Asif\Desktop\New_version_CogniLink\venv\lib\site-packages\azure\core\tracing\decorator.py"", line 78, in wrapper_use_tracer
    return func(*args, **kwargs)
  File ""C:\Users\Asif\Desktop\New_version_CogniLink\venv\lib\site-packages\azure\storage\blob\_blob_client.py"", line 765, in upload_blob
    return upload_block_blob(**options)
  File ""C:\Users\Asif\Desktop\New_version_CogniLink\venv\lib\site-packages\azure\storage\blob\_upload_helpers.py"", line 195, in upload_block_blob
    process_storage_error(error)
  File ""C:\Users\Asif\Desktop\New_version_CogniLink\venv\lib\site-packages\azure\storage\blob\_shared\response_handlers.py"", line 184, in process_storage_error
    exec(""raise error from None"")   # pylint: disable=exec-used # nosec
  File ""<string>"", line 1, in <module>
azure.core.exceptions.HttpResponseError: Value for one of the query parameters specified in the request URI is invalid.
RequestId:b21fe057-201e-000c-2686-b99bf7000000
Time:2024-06-08T09:31:42.2310040Z
ErrorCode:InvalidQueryParameterValue
queryparametername:snapshot
queryparametervalue:asif24
Content: <?xml version=""1.0"" encoding=""utf-8""?>
<Error><Code>InvalidQueryParameterValue</Code><Message>Value for one of the query parameters specified in the request URI is invalid.
RequestId:b21fe057-201e-000c-2686-b99bf7000000
Time:2024-06-08T09:31:42.2310040Z</Message><QueryParameterName>snapshot</QueryParameterName><QueryParameterValue>asif24</QueryParameterValue></Error>"
2024-06-08 15:01:42,ERROR,asif24,create_or_pass_folder,206,0,"Function create_or_pass_folder Error creating folder'asif24': Value for one of the query parameters specified in the request URI is invalid.
RequestId:b21fe057-201e-000c-2686-b99bf7000000
Time:2024-06-08T09:31:42.2310040Z
ErrorCode:InvalidQueryParameterValue
queryparametername:snapshot
queryparametervalue:asif24
Content: <?xml version=""1.0"" encoding=""utf-8""?>
<Error><Code>InvalidQueryParameterValue</Code><Message>Value for one of the query parameters specified in the request URI is invalid.
RequestId:b21fe057-201e-000c-2686-b99bf7000000
Time:2024-06-08T09:31:42.2310040Z</Message><QueryParameterName>snapshot</QueryParameterName><QueryParameterValue>asif24</QueryParameterValue></Error> ","Function create_or_pass_folder Error creating folder'asif24': Value for one of the query parameters specified in the request URI is invalid.
RequestId:b21fe057-201e-000c-2686-b99bf7000000
Time:2024-06-08T09:31:42.2310040Z
ErrorCode:InvalidQueryParameterValue
queryparametername:snapshot
queryparametervalue:asif24
Content: <?xml version=""1.0"" encoding=""utf-8""?>
<Error><Code>InvalidQueryParameterValue</Code><Message>Value for one of the query parameters specified in the request URI is invalid.
RequestId:b21fe057-201e-000c-2686-b99bf7000000
Time:2024-06-08T09:31:42.2310040Z</Message><QueryParameterName>snapshot</QueryParameterName><QueryParameterValue>asif24</QueryParameterValue></Error> 
Traceback (most recent call last):
  File ""C:\Users\Asif\Desktop\New_version_CogniLink\app.py"", line 190, in create_or_pass_folder
    container_client.get_blob_client(container_name, user_folder).upload_blob("""")
  File ""C:\Users\Asif\Desktop\New_version_CogniLink\venv\lib\site-packages\azure\core\tracing\decorator.py"", line 78, in wrapper_use_tracer
    return func(*args, **kwargs)
  File ""C:\Users\Asif\Desktop\New_version_CogniLink\venv\lib\site-packages\azure\storage\blob\_blob_client.py"", line 765, in upload_blob
    return upload_block_blob(**options)
  File ""C:\Users\Asif\Desktop\New_version_CogniLink\venv\lib\site-packages\azure\storage\blob\_upload_helpers.py"", line 195, in upload_block_blob
    process_storage_error(error)
  File ""C:\Users\Asif\Desktop\New_version_CogniLink\venv\lib\site-packages\azure\storage\blob\_shared\response_handlers.py"", line 184, in process_storage_error
    exec(""raise error from None"")   # pylint: disable=exec-used # nosec
  File ""<string>"", line 1, in <module>
azure.core.exceptions.HttpResponseError: Value for one of the query parameters specified in the request URI is invalid.
RequestId:b21fe057-201e-000c-2686-b99bf7000000
Time:2024-06-08T09:31:42.2310040Z
ErrorCode:InvalidQueryParameterValue
queryparametername:snapshot
queryparametervalue:asif24
Content: <?xml version=""1.0"" encoding=""utf-8""?>
<Error><Code>InvalidQueryParameterValue</Code><Message>Value for one of the query parameters specified in the request URI is invalid.
RequestId:b21fe057-201e-000c-2686-b99bf7000000
Time:2024-06-08T09:31:42.2310040Z</Message><QueryParameterName>snapshot</QueryParameterName><QueryParameterValue>asif24</QueryParameterValue></Error>"
2024-06-08 15:01:42,INFO,asif24,home,1406,1,User asif24 logged in successfully,
2024-06-08 15:01:42,INFO,asif24,update_bar_chart_from_blob,317,1,Function update_bar_chart_from_blob successfully Return blob_list,
2024-06-08 15:01:42,INFO,asif24,update_bar_chart_from_blob,317,1,Function update_bar_chart_from_blob successfully Return blob_list,
2024-06-08 15:01:44,INFO,asif24,get_data_source,1996,1,table_update route successfully send data,
2024-06-08 15:03:27,INFO,asif24,update_bar_chart_from_blob,317,1,Function update_bar_chart_from_blob successfully Return blob_list,
2024-06-08 15:03:28,INFO,asif24,get_data_source,1996,1,table_update route successfully send data,
2024-06-08 15:04:22,INFO,asif24,Cogni_button,1713,1,CogniLink load button pressed,
2024-06-08 15:04:23,ERROR,asif24,Cogni_button,1733,0,Unhandled exception occurred,"Unhandled exception occurred
Traceback (most recent call last):
  File ""C:\Users\Asif\Desktop\New_version_CogniLink\app.py"", line 1717, in Cogni_button
    response = update_when_file_delete()
  File ""C:\Users\Asif\Desktop\New_version_CogniLink\app.py"", line 385, in update_when_file_delete
    for result in results:
  File ""C:\Users\Asif\Desktop\New_version_CogniLink\venv\lib\site-packages\azure\search\documents\_paging.py"", line 54, in __next__
    return next(self._page_iterator)
  File ""C:\Users\Asif\Desktop\New_version_CogniLink\venv\lib\site-packages\azure\core\paging.py"", line 75, in __next__
    self._response = self._get_next(self.continuation_token)
  File ""C:\Users\Asif\Desktop\New_version_CogniLink\venv\lib\site-packages\azure\search\documents\_paging.py"", line 124, in _get_next_cb
    return self._client.documents.search_post(search_request=self._initial_query.request, **self._kwargs)
  File ""C:\Users\Asif\Desktop\New_version_CogniLink\venv\lib\site-packages\azure\core\tracing\decorator.py"", line 78, in wrapper_use_tracer
    return func(*args, **kwargs)
  File ""C:\Users\Asif\Desktop\New_version_CogniLink\venv\lib\site-packages\azure\search\documents\_generated\operations\_documents_operations.py"", line 754, in search_post
    map_error(status_code=response.status_code, response=response, error_map=error_map)
  File ""C:\Users\Asif\Desktop\New_version_CogniLink\venv\lib\site-packages\azure\core\exceptions.py"", line 165, in map_error
    raise error
azure.core.exceptions.ResourceNotFoundError: () The index 'asif24' for service 'cognilink-vectordb' was not found.
Code: 
Message: The index 'asif24' for service 'cognilink-vectordb' was not found."
2024-06-08 15:04:39,INFO,asif24,Cogni_button,1713,1,CogniLink load button pressed,
2024-06-08 15:04:40,ERROR,asif24,Cogni_button,1733,0,Unhandled exception occurred,"Unhandled exception occurred
Traceback (most recent call last):
  File ""C:\Users\Asif\Desktop\New_version_CogniLink\app.py"", line 1717, in Cogni_button
    response = update_when_file_delete()
  File ""C:\Users\Asif\Desktop\New_version_CogniLink\app.py"", line 385, in update_when_file_delete
    for result in results:
  File ""C:\Users\Asif\Desktop\New_version_CogniLink\venv\lib\site-packages\azure\search\documents\_paging.py"", line 54, in __next__
    return next(self._page_iterator)
  File ""C:\Users\Asif\Desktop\New_version_CogniLink\venv\lib\site-packages\azure\core\paging.py"", line 75, in __next__
    self._response = self._get_next(self.continuation_token)
  File ""C:\Users\Asif\Desktop\New_version_CogniLink\venv\lib\site-packages\azure\search\documents\_paging.py"", line 124, in _get_next_cb
    return self._client.documents.search_post(search_request=self._initial_query.request, **self._kwargs)
  File ""C:\Users\Asif\Desktop\New_version_CogniLink\venv\lib\site-packages\azure\core\tracing\decorator.py"", line 78, in wrapper_use_tracer
    return func(*args, **kwargs)
  File ""C:\Users\Asif\Desktop\New_version_CogniLink\venv\lib\site-packages\azure\search\documents\_generated\operations\_documents_operations.py"", line 754, in search_post
    map_error(status_code=response.status_code, response=response, error_map=error_map)
  File ""C:\Users\Asif\Desktop\New_version_CogniLink\venv\lib\site-packages\azure\core\exceptions.py"", line 165, in map_error
    raise error
azure.core.exceptions.ResourceNotFoundError: () The index 'asif24' for service 'cognilink-vectordb' was not found.
Code: 
Message: The index 'asif24' for service 'cognilink-vectordb' was not found."
2024-06-08 15:04:50,INFO,asif24,update_bar_chart_from_blob,317,1,Function update_bar_chart_from_blob successfully Return blob_list,
2024-06-08 15:04:51,INFO,asif24,get_data_source,1996,1,table_update route successfully send data,
2024-06-08 15:05:02,INFO,asif24,upload_to_blob,255,1,Function upload_to_blob successfully created blob_client.url,
2024-06-08 15:05:02,INFO,asif24,update_bar_chart_from_blob,317,1,Function update_bar_chart_from_blob successfully Return blob_list,
2024-06-08 15:05:02,INFO,asif24,popup_form,1530,1,Data Uploaded Successfully,
2024-06-08 15:05:03,INFO,asif24,get_data_source,1996,1,table_update route successfully send data,
2024-06-08 15:05:12,INFO,asif24,get_data_source,1996,1,table_update route successfully send data,
2024-06-08 15:05:12,INFO,asif24,get_data_source,1996,1,table_update route successfully send data,
2024-06-08 15:05:13,INFO,asif24,update_bar_chart_from_blob,317,1,Function update_bar_chart_from_blob successfully Return blob_list,
2024-06-08 15:05:13,INFO,asif24,delete_files,1958,1,Selected vault files deleted successfully,
2024-06-08 15:05:13,INFO,asif24,get_data_source,1996,1,table_update route successfully send data,
2024-06-08 15:05:26,INFO,asif24,upload_to_blob,255,1,Function upload_to_blob successfully created blob_client.url,
2024-06-08 15:05:26,INFO,asif24,update_bar_chart_from_blob,317,1,Function update_bar_chart_from_blob successfully Return blob_list,
2024-06-08 15:05:26,INFO,asif24,popup_form,1530,1,Data Uploaded Successfully,
2024-06-08 15:05:26,INFO,asif24,get_data_source,1996,1,table_update route successfully send data,
2024-06-08 15:05:27,INFO,asif24,Cogni_button,1713,1,CogniLink load button pressed,
2024-06-08 15:05:29,ERROR,asif24,Cogni_button,1733,0,Unhandled exception occurred,"Unhandled exception occurred
Traceback (most recent call last):
  File ""C:\Users\Asif\Desktop\New_version_CogniLink\app.py"", line 1717, in Cogni_button
    response = update_when_file_delete()
  File ""C:\Users\Asif\Desktop\New_version_CogniLink\app.py"", line 385, in update_when_file_delete
    for result in results:
  File ""C:\Users\Asif\Desktop\New_version_CogniLink\venv\lib\site-packages\azure\search\documents\_paging.py"", line 54, in __next__
    return next(self._page_iterator)
  File ""C:\Users\Asif\Desktop\New_version_CogniLink\venv\lib\site-packages\azure\core\paging.py"", line 75, in __next__
    self._response = self._get_next(self.continuation_token)
  File ""C:\Users\Asif\Desktop\New_version_CogniLink\venv\lib\site-packages\azure\search\documents\_paging.py"", line 124, in _get_next_cb
    return self._client.documents.search_post(search_request=self._initial_query.request, **self._kwargs)
  File ""C:\Users\Asif\Desktop\New_version_CogniLink\venv\lib\site-packages\azure\core\tracing\decorator.py"", line 78, in wrapper_use_tracer
    return func(*args, **kwargs)
  File ""C:\Users\Asif\Desktop\New_version_CogniLink\venv\lib\site-packages\azure\search\documents\_generated\operations\_documents_operations.py"", line 754, in search_post
    map_error(status_code=response.status_code, response=response, error_map=error_map)
  File ""C:\Users\Asif\Desktop\New_version_CogniLink\venv\lib\site-packages\azure\core\exceptions.py"", line 165, in map_error
    raise error
azure.core.exceptions.ResourceNotFoundError: () The index 'asif24' for service 'cognilink-vectordb' was not found.
Code: 
Message: The index 'asif24' for service 'cognilink-vectordb' was not found."
2024-06-08 15:05:31,INFO,asif24,Cogni_button,1713,1,CogniLink load button pressed,
2024-06-08 15:05:32,ERROR,asif24,Cogni_button,1733,0,Unhandled exception occurred,"Unhandled exception occurred
Traceback (most recent call last):
  File ""C:\Users\Asif\Desktop\New_version_CogniLink\app.py"", line 1717, in Cogni_button
    response = update_when_file_delete()
  File ""C:\Users\Asif\Desktop\New_version_CogniLink\app.py"", line 385, in update_when_file_delete
    for result in results:
  File ""C:\Users\Asif\Desktop\New_version_CogniLink\venv\lib\site-packages\azure\search\documents\_paging.py"", line 54, in __next__
    return next(self._page_iterator)
  File ""C:\Users\Asif\Desktop\New_version_CogniLink\venv\lib\site-packages\azure\core\paging.py"", line 75, in __next__
    self._response = self._get_next(self.continuation_token)
  File ""C:\Users\Asif\Desktop\New_version_CogniLink\venv\lib\site-packages\azure\search\documents\_paging.py"", line 124, in _get_next_cb
    return self._client.documents.search_post(search_request=self._initial_query.request, **self._kwargs)
  File ""C:\Users\Asif\Desktop\New_version_CogniLink\venv\lib\site-packages\azure\core\tracing\decorator.py"", line 78, in wrapper_use_tracer
    return func(*args, **kwargs)
  File ""C:\Users\Asif\Desktop\New_version_CogniLink\venv\lib\site-packages\azure\search\documents\_generated\operations\_documents_operations.py"", line 754, in search_post
    map_error(status_code=response.status_code, response=response, error_map=error_map)
  File ""C:\Users\Asif\Desktop\New_version_CogniLink\venv\lib\site-packages\azure\core\exceptions.py"", line 165, in map_error
    raise error
azure.core.exceptions.ResourceNotFoundError: () The index 'asif24' for service 'cognilink-vectordb' was not found.
Code: 
Message: The index 'asif24' for service 'cognilink-vectordb' was not found."
2024-06-08 15:05:58,INFO,asif24,Cogni_button,1713,1,CogniLink load button pressed,
2024-06-08 15:05:59,ERROR,asif24,Cogni_button,1733,0,Unhandled exception occurred,"Unhandled exception occurred
Traceback (most recent call last):
  File ""C:\Users\Asif\Desktop\New_version_CogniLink\app.py"", line 1717, in Cogni_button
    response = update_when_file_delete()
  File ""C:\Users\Asif\Desktop\New_version_CogniLink\app.py"", line 385, in update_when_file_delete
    for result in results:
  File ""C:\Users\Asif\Desktop\New_version_CogniLink\venv\lib\site-packages\azure\search\documents\_paging.py"", line 54, in __next__
    return next(self._page_iterator)
  File ""C:\Users\Asif\Desktop\New_version_CogniLink\venv\lib\site-packages\azure\core\paging.py"", line 75, in __next__
    self._response = self._get_next(self.continuation_token)
  File ""C:\Users\Asif\Desktop\New_version_CogniLink\venv\lib\site-packages\azure\search\documents\_paging.py"", line 124, in _get_next_cb
    return self._client.documents.search_post(search_request=self._initial_query.request, **self._kwargs)
  File ""C:\Users\Asif\Desktop\New_version_CogniLink\venv\lib\site-packages\azure\core\tracing\decorator.py"", line 78, in wrapper_use_tracer
    return func(*args, **kwargs)
  File ""C:\Users\Asif\Desktop\New_version_CogniLink\venv\lib\site-packages\azure\search\documents\_generated\operations\_documents_operations.py"", line 754, in search_post
    map_error(status_code=response.status_code, response=response, error_map=error_map)
  File ""C:\Users\Asif\Desktop\New_version_CogniLink\venv\lib\site-packages\azure\core\exceptions.py"", line 165, in map_error
    raise error
azure.core.exceptions.ResourceNotFoundError: () The index 'asif24' for service 'cognilink-vectordb' was not found.
Code: 
Message: The index 'asif24' for service 'cognilink-vectordb' was not found."
