timestamp,category,user_id,function,line_number,flag,message,exception
2024-06-10 12:44:24,ERROR,asif24,create_or_pass_folder,199,0,Function create_or_pass_folder error,"Function create_or_pass_folder error
Traceback (most recent call last):
  File ""C:\Users\Asif\Desktop\New_version_CogniLink\app.py"", line 192, in create_or_pass_folder
    container_client.get_blob_client(container_name, user_folder).upload_blob("""")
  File ""C:\Users\Asif\Desktop\New_version_CogniLink\venv\lib\site-packages\azure\core\tracing\decorator.py"", line 78, in wrapper_use_tracer
    return func(*args, **kwargs)
  File ""C:\Users\Asif\Desktop\New_version_CogniLink\venv\lib\site-packages\azure\storage\blob\_blob_client.py"", line 765, in upload_blob
    return upload_block_blob(**options)
  File ""C:\Users\Asif\Desktop\New_version_CogniLink\venv\lib\site-packages\azure\storage\blob\_upload_helpers.py"", line 195, in upload_block_blob
    process_storage_error(error)
  File ""C:\Users\Asif\Desktop\New_version_CogniLink\venv\lib\site-packages\azure\storage\blob\_shared\response_handlers.py"", line 184, in process_storage_error
    exec(""raise error from None"")   # pylint: disable=exec-used # nosec
  File ""<string>"", line 1, in <module>
azure.core.exceptions.HttpResponseError: Value for one of the query parameters specified in the request URI is invalid.
RequestId:42ca25b9-d01e-003b-5205-bb3758000000
Time:2024-06-10T07:14:23.8597888Z
ErrorCode:InvalidQueryParameterValue
queryparametername:snapshot
queryparametervalue:asif24
Content: <?xml version=""1.0"" encoding=""utf-8""?>
<Error><Code>InvalidQueryParameterValue</Code><Message>Value for one of the query parameters specified in the request URI is invalid.
RequestId:42ca25b9-d01e-003b-5205-bb3758000000
Time:2024-06-10T07:14:23.8597888Z</Message><QueryParameterName>snapshot</QueryParameterName><QueryParameterValue>asif24</QueryParameterValue></Error>"
2024-06-10 12:44:24,ERROR,asif24,create_or_pass_folder,208,0,"Function create_or_pass_folder Error creating folder'asif24': Value for one of the query parameters specified in the request URI is invalid.
RequestId:42ca25b9-d01e-003b-5205-bb3758000000
Time:2024-06-10T07:14:23.8597888Z
ErrorCode:InvalidQueryParameterValue
queryparametername:snapshot
queryparametervalue:asif24
Content: <?xml version=""1.0"" encoding=""utf-8""?>
<Error><Code>InvalidQueryParameterValue</Code><Message>Value for one of the query parameters specified in the request URI is invalid.
RequestId:42ca25b9-d01e-003b-5205-bb3758000000
Time:2024-06-10T07:14:23.8597888Z</Message><QueryParameterName>snapshot</QueryParameterName><QueryParameterValue>asif24</QueryParameterValue></Error> ","Function create_or_pass_folder Error creating folder'asif24': Value for one of the query parameters specified in the request URI is invalid.
RequestId:42ca25b9-d01e-003b-5205-bb3758000000
Time:2024-06-10T07:14:23.8597888Z
ErrorCode:InvalidQueryParameterValue
queryparametername:snapshot
queryparametervalue:asif24
Content: <?xml version=""1.0"" encoding=""utf-8""?>
<Error><Code>InvalidQueryParameterValue</Code><Message>Value for one of the query parameters specified in the request URI is invalid.
RequestId:42ca25b9-d01e-003b-5205-bb3758000000
Time:2024-06-10T07:14:23.8597888Z</Message><QueryParameterName>snapshot</QueryParameterName><QueryParameterValue>asif24</QueryParameterValue></Error> 
Traceback (most recent call last):
  File ""C:\Users\Asif\Desktop\New_version_CogniLink\app.py"", line 192, in create_or_pass_folder
    container_client.get_blob_client(container_name, user_folder).upload_blob("""")
  File ""C:\Users\Asif\Desktop\New_version_CogniLink\venv\lib\site-packages\azure\core\tracing\decorator.py"", line 78, in wrapper_use_tracer
    return func(*args, **kwargs)
  File ""C:\Users\Asif\Desktop\New_version_CogniLink\venv\lib\site-packages\azure\storage\blob\_blob_client.py"", line 765, in upload_blob
    return upload_block_blob(**options)
  File ""C:\Users\Asif\Desktop\New_version_CogniLink\venv\lib\site-packages\azure\storage\blob\_upload_helpers.py"", line 195, in upload_block_blob
    process_storage_error(error)
  File ""C:\Users\Asif\Desktop\New_version_CogniLink\venv\lib\site-packages\azure\storage\blob\_shared\response_handlers.py"", line 184, in process_storage_error
    exec(""raise error from None"")   # pylint: disable=exec-used # nosec
  File ""<string>"", line 1, in <module>
azure.core.exceptions.HttpResponseError: Value for one of the query parameters specified in the request URI is invalid.
RequestId:42ca25b9-d01e-003b-5205-bb3758000000
Time:2024-06-10T07:14:23.8597888Z
ErrorCode:InvalidQueryParameterValue
queryparametername:snapshot
queryparametervalue:asif24
Content: <?xml version=""1.0"" encoding=""utf-8""?>
<Error><Code>InvalidQueryParameterValue</Code><Message>Value for one of the query parameters specified in the request URI is invalid.
RequestId:42ca25b9-d01e-003b-5205-bb3758000000
Time:2024-06-10T07:14:23.8597888Z</Message><QueryParameterName>snapshot</QueryParameterName><QueryParameterValue>asif24</QueryParameterValue></Error>"
2024-06-10 12:44:24,INFO,asif24,home,1408,1,User asif24 logged in successfully,
2024-06-10 12:44:24,INFO,asif24,update_bar_chart_from_blob,319,1,Function update_bar_chart_from_blob successfully Return blob_list,
2024-06-10 12:44:27,INFO,asif24,update_bar_chart_from_blob,319,1,Function update_bar_chart_from_blob successfully Return blob_list,
2024-06-10 12:44:29,INFO,asif24,get_data_source,2058,1,table_update route successfully send data,
2024-06-10 12:44:39,INFO,asif24,perform_lda____summ,1124,1,Summary topics generated.,
2024-06-10 12:44:39,INFO,asif24,handle_summary_input,1854,1,Summary Generated in 6.675168514251709 seconds,
2024-06-10 12:44:46,INFO,asif24,update_bar_chart_from_blob,319,1,Function update_bar_chart_from_blob successfully Return blob_list,
2024-06-10 12:44:47,INFO,asif24,get_data_source,2058,1,table_update route successfully send data,
2024-06-10 12:45:06,INFO,asif24,upload_to_blob,257,1,Function upload_to_blob successfully created blob_client.url,
2024-06-10 12:45:07,INFO,asif24,update_bar_chart_from_blob,319,1,Function update_bar_chart_from_blob successfully Return blob_list,
2024-06-10 12:45:07,INFO,asif24,popup_form,1539,1,Data Uploaded Successfully,
2024-06-10 12:45:07,INFO,asif24,get_data_source,2058,1,table_update route successfully send data,
2024-06-10 12:45:08,INFO,asif24,Cogni_button,1722,1,CogniLink load button pressed,
2024-06-10 12:45:25,INFO,asif24,update_bar_chart_from_blob,319,1,Function update_bar_chart_from_blob successfully Return blob_list,
2024-06-10 12:45:28,INFO,asif24,update_when_file_delete,607,1,Function update_when_file_delete Data Loaded Successfully,
2024-06-10 12:45:28,INFO,asif24,Cogni_button,1734,1,Load Data Function executed in 19.875837802886963 seconds,
2024-06-10 12:45:29,INFO,asif24,get_data_source,2058,1,table_update route successfully send data,
2024-06-10 12:45:52,ERROR,asif24,handle_summary_input,1860,0,Summary generation error,"Summary generation error
Traceback (most recent call last):
  File ""C:\Users\Asif\Desktop\New_version_CogniLink\app.py"", line 1829, in handle_summary_input
    metadata = json.loads(file_info['metadata'])
  File ""C:\Users\Asif\AppData\Local\Programs\Python\Python310\lib\json\__init__.py"", line 346, in loads
    return _default_decoder.decode(s)
  File ""C:\Users\Asif\AppData\Local\Programs\Python\Python310\lib\json\decoder.py"", line 340, in decode
    raise JSONDecodeError(""Extra data"", s, end)
json.decoder.JSONDecodeError: Extra data: line 2 column 1 (char 130)"
2024-06-10 12:46:10,INFO,asif24,handle_clear_chat_summ,1888,1,Summary chat cleared,
2024-06-10 12:46:20,ERROR,asif24,handle_summary_input,1860,0,Summary generation error,"Summary generation error
Traceback (most recent call last):
  File ""C:\Users\Asif\Desktop\New_version_CogniLink\app.py"", line 1829, in handle_summary_input
    metadata = json.loads(file_info['metadata'])
  File ""C:\Users\Asif\AppData\Local\Programs\Python\Python310\lib\json\__init__.py"", line 346, in loads
    return _default_decoder.decode(s)
  File ""C:\Users\Asif\AppData\Local\Programs\Python\Python310\lib\json\decoder.py"", line 340, in decode
    raise JSONDecodeError(""Extra data"", s, end)
json.decoder.JSONDecodeError: Extra data: line 2 column 1 (char 130)"
2024-06-10 12:46:35,INFO,asif24,perform_lda___Q_A,1034,1,QnA topics generated.,
2024-06-10 12:46:35,INFO,asif24,handle_ask_question,1958,1,Answer Generated in 8.413265705108643 seconds,
2024-06-10 12:46:44,ERROR,asif24,handle_summary_input,1860,0,Summary generation error,"Summary generation error
Traceback (most recent call last):
  File ""C:\Users\Asif\Desktop\New_version_CogniLink\app.py"", line 1829, in handle_summary_input
    metadata = json.loads(file_info['metadata'])
  File ""C:\Users\Asif\AppData\Local\Programs\Python\Python310\lib\json\__init__.py"", line 346, in loads
    return _default_decoder.decode(s)
  File ""C:\Users\Asif\AppData\Local\Programs\Python\Python310\lib\json\decoder.py"", line 340, in decode
    raise JSONDecodeError(""Extra data"", s, end)
json.decoder.JSONDecodeError: Extra data: line 2 column 1 (char 130)"
