timestamp,category,user_id,function,line_number,flag,message,exception
2024-06-10 15:51:07,ERROR,asif24,create_or_pass_folder,199,0,Function create_or_pass_folder error,"Function create_or_pass_folder error
Traceback (most recent call last):
  File ""C:\Users\Asif\Desktop\New_version_CogniLink\app.py"", line 192, in create_or_pass_folder
    container_client.get_blob_client(container_name, user_folder).upload_blob("""")
  File ""C:\Users\Asif\Desktop\New_version_CogniLink\venv\lib\site-packages\azure\core\tracing\decorator.py"", line 78, in wrapper_use_tracer
    return func(*args, **kwargs)
  File ""C:\Users\Asif\Desktop\New_version_CogniLink\venv\lib\site-packages\azure\storage\blob\_blob_client.py"", line 765, in upload_blob
    return upload_block_blob(**options)
  File ""C:\Users\Asif\Desktop\New_version_CogniLink\venv\lib\site-packages\azure\storage\blob\_upload_helpers.py"", line 195, in upload_block_blob
    process_storage_error(error)
  File ""C:\Users\Asif\Desktop\New_version_CogniLink\venv\lib\site-packages\azure\storage\blob\_shared\response_handlers.py"", line 184, in process_storage_error
    exec(""raise error from None"")   # pylint: disable=exec-used # nosec
  File ""<string>"", line 1, in <module>
azure.core.exceptions.HttpResponseError: Value for one of the query parameters specified in the request URI is invalid.
RequestId:08b53e32-201e-0048-6f1f-bb479b000000
Time:2024-06-10T10:21:06.7073554Z
ErrorCode:InvalidQueryParameterValue
queryparametername:snapshot
queryparametervalue:asif24
Content: <?xml version=""1.0"" encoding=""utf-8""?>
<Error><Code>InvalidQueryParameterValue</Code><Message>Value for one of the query parameters specified in the request URI is invalid.
RequestId:08b53e32-201e-0048-6f1f-bb479b000000
Time:2024-06-10T10:21:06.7073554Z</Message><QueryParameterName>snapshot</QueryParameterName><QueryParameterValue>asif24</QueryParameterValue></Error>"
2024-06-10 15:51:07,ERROR,asif24,create_or_pass_folder,208,0,"Function create_or_pass_folder Error creating folder'asif24': Value for one of the query parameters specified in the request URI is invalid.
RequestId:08b53e32-201e-0048-6f1f-bb479b000000
Time:2024-06-10T10:21:06.7073554Z
ErrorCode:InvalidQueryParameterValue
queryparametername:snapshot
queryparametervalue:asif24
Content: <?xml version=""1.0"" encoding=""utf-8""?>
<Error><Code>InvalidQueryParameterValue</Code><Message>Value for one of the query parameters specified in the request URI is invalid.
RequestId:08b53e32-201e-0048-6f1f-bb479b000000
Time:2024-06-10T10:21:06.7073554Z</Message><QueryParameterName>snapshot</QueryParameterName><QueryParameterValue>asif24</QueryParameterValue></Error> ","Function create_or_pass_folder Error creating folder'asif24': Value for one of the query parameters specified in the request URI is invalid.
RequestId:08b53e32-201e-0048-6f1f-bb479b000000
Time:2024-06-10T10:21:06.7073554Z
ErrorCode:InvalidQueryParameterValue
queryparametername:snapshot
queryparametervalue:asif24
Content: <?xml version=""1.0"" encoding=""utf-8""?>
<Error><Code>InvalidQueryParameterValue</Code><Message>Value for one of the query parameters specified in the request URI is invalid.
RequestId:08b53e32-201e-0048-6f1f-bb479b000000
Time:2024-06-10T10:21:06.7073554Z</Message><QueryParameterName>snapshot</QueryParameterName><QueryParameterValue>asif24</QueryParameterValue></Error> 
Traceback (most recent call last):
  File ""C:\Users\Asif\Desktop\New_version_CogniLink\app.py"", line 192, in create_or_pass_folder
    container_client.get_blob_client(container_name, user_folder).upload_blob("""")
  File ""C:\Users\Asif\Desktop\New_version_CogniLink\venv\lib\site-packages\azure\core\tracing\decorator.py"", line 78, in wrapper_use_tracer
    return func(*args, **kwargs)
  File ""C:\Users\Asif\Desktop\New_version_CogniLink\venv\lib\site-packages\azure\storage\blob\_blob_client.py"", line 765, in upload_blob
    return upload_block_blob(**options)
  File ""C:\Users\Asif\Desktop\New_version_CogniLink\venv\lib\site-packages\azure\storage\blob\_upload_helpers.py"", line 195, in upload_block_blob
    process_storage_error(error)
  File ""C:\Users\Asif\Desktop\New_version_CogniLink\venv\lib\site-packages\azure\storage\blob\_shared\response_handlers.py"", line 184, in process_storage_error
    exec(""raise error from None"")   # pylint: disable=exec-used # nosec
  File ""<string>"", line 1, in <module>
azure.core.exceptions.HttpResponseError: Value for one of the query parameters specified in the request URI is invalid.
RequestId:08b53e32-201e-0048-6f1f-bb479b000000
Time:2024-06-10T10:21:06.7073554Z
ErrorCode:InvalidQueryParameterValue
queryparametername:snapshot
queryparametervalue:asif24
Content: <?xml version=""1.0"" encoding=""utf-8""?>
<Error><Code>InvalidQueryParameterValue</Code><Message>Value for one of the query parameters specified in the request URI is invalid.
RequestId:08b53e32-201e-0048-6f1f-bb479b000000
Time:2024-06-10T10:21:06.7073554Z</Message><QueryParameterName>snapshot</QueryParameterName><QueryParameterValue>asif24</QueryParameterValue></Error>"
2024-06-10 15:51:07,INFO,asif24,home,1377,1,User asif24 logged in successfully,
2024-06-10 15:51:07,INFO,asif24,update_bar_chart_from_blob,319,1,Function update_bar_chart_from_blob successfully Return blob_list,
2024-06-10 15:51:10,INFO,asif24,update_bar_chart_from_blob,319,1,Function update_bar_chart_from_blob successfully Return blob_list,
2024-06-10 15:51:14,INFO,asif24,get_data_source,2055,1,table_update route successfully send data,
2024-06-10 15:51:23,ERROR,asif24,handle_ask_question,1960,0,Ask CogniLink answer generation error,"Ask CogniLink answer generation error
Traceback (most recent call last):
  File ""C:\Users\Asif\Desktop\New_version_CogniLink\app.py"", line 1918, in handle_ask_question
    conversation = get_conversation_chain(vector_store)
  File ""C:\Users\Asif\Desktop\New_version_CogniLink\app.py"", line 767, in get_conversation_chain
    conversation_chain = ConversationalRetrievalChain.from_llm(
  File ""C:\Users\Asif\Desktop\New_version_CogniLink\venv\lib\site-packages\langchain\chains\conversational_retrieval\base.py"", line 463, in from_llm
    return cls(
  File ""C:\Users\Asif\Desktop\New_version_CogniLink\venv\lib\site-packages\langchain_core\_api\deprecation.py"", line 183, in warn_if_direct_instance
    return wrapped(self, *args, **kwargs)
  File ""C:\Users\Asif\Desktop\New_version_CogniLink\venv\lib\site-packages\pydantic\v1\main.py"", line 341, in __init__
    raise validation_error
pydantic.v1.error_wrappers.ValidationError: 1 validation error for ConversationalRetrievalChain
question_prompt
  extra fields not permitted (type=value_error.extra)"
